Workbook

Sheet Q1 - Contribution
A1: Elementary Category | B1: Broader Bucket | C1: May 2023 Index Value
A2: Cereals and products | B2: Food | C2: ='Imputed Data'!E126 -> 173.7
A3: Meat and fish | B3: Food | C3: ='Imputed Data'!F126 -> 214.3
A4: Egg | B4: Food | C4: ='Imputed Data'!G126 -> 173.2
A5: Milk and products | B5: Food | C5: ='Imputed Data'!H126 -> 179.5
A6: Oils and fats | B6: Food | C6: ='Imputed Data'!I126 -> 170
A7: Fruits | B7: Food | C7: ='Imputed Data'!J126 -> 172.2
A8: Vegetables | B8: Food | C8: ='Imputed Data'!K126 -> 161
A9: Pulses and products | B9: Food | C9: ='Imputed Data'!L126 -> 175.6
A10: Sugar and Confectionery | B10: Food | C10: ='Imputed Data'!M126 -> 122.7
A11: Spices | B11: Food | C11: ='Imputed Data'!N126 -> 218
A12: Prepared meals, snacks etc. | B12: Food | C12: ='Imputed Data'!P126 -> 194.2
A13: Non-alcoholic beverages | B13: Miscellaneous/Discretionary | C13: ='Imputed Data'!O126 -> 173.4
A14: Pan, tobacco and intoxicants | B14: Miscellaneous/Discretionary | C14: ='Imputed Data'!R126 -> 201
A15: Recreation and amusement | B15: Miscellaneous/Discretionary | C15: ='Imputed Data'!AA126 -> 171.2
A16: Personal care and effects | B16: Miscellaneous/Discretionary | C16: ='Imputed Data'!AC126 -> 185.2
A17: Clothing | B17: Clothing & Footwear | C17: ='Imputed Data'!S126 -> 187.3
A18: Footwear | B18: Clothing & Footwear | C18: ='Imputed Data'!T126 -> 179.7
A19: Housing | B19: Housing | C19: ='Imputed Data'!V126 -> 175.6
A20: Household goods and services | B20: Housing | C20: ='Imputed Data'!X126 -> 175.2
A21: Fuel and light | B21: Fuel & Light | C21: ='Imputed Data'!W126 -> 182.8
A22: Health | B22: Health | C22: ='Imputed Data'!Y126 -> 185.7
A23: Transport and communication | B23: Transport & Communication | C23: ='Imputed Data'!Z126 -> 164.8
A24: Education | B24: Education | C24: ='Imputed Data'!AB126 -> 177.1
A25: Total (all elementary items) | C25: =SUBTOTAL(109,Table4[May 2023 Index Value]) -> 4113.4
A28: Broader Bucket | B28: Sum of Index Values | C28: Contribution % | E28: Food is the highest-contributing broader category at 47.51%, broadly in line with food's large share of Indian household spending. Note that Food has 11 of the 23 items, so this share partly reflects the number of items in the bucket. It was calculated by grouping the 23 elementary (non-aggregate) CPI items into 8 broader buckets and summing their raw index values under an equal-weighting assumption, per the brief's instruction. MoSPI's own aggregate columns were not used, because they already include the elementary items and would have double-counted them.
A29: Food | B29: =SUMIF($B$2:$B$24,A29,$C$2:$C$24) -> 1954.4 | C29: =B29/$C$25 -> 0.47513006
A30: Miscellaneous/Discretionary | B30: =SUMIF($B$2:$B$24,A30,$C$2:$C$24) -> 730.8 | C30: =B30/$C$25 -> 0.17766325
A31: Clothing & Footwear | B31: =SUMIF($B$2:$B$24,A31,$C$2:$C$24) -> 367 | C31: =B31/$C$25 -> 0.089220596
A32: Housing | B32: =SUMIF($B$2:$B$24,A32,$C$2:$C$24) -> 350.8 | C32: =B32/$C$25 -> 0.085282248
A33: Fuel & Light | B33: =SUMIF($B$2:$B$24,A33,$C$2:$C$24) -> 182.8 | C33: =B33/$C$25 -> 0.044440123
A34: Health | B34: =SUMIF($B$2:$B$24,A34,$C$2:$C$24) -> 185.7 | C34: =B34/$C$25 -> 0.045145135
A35: Transport & Communication | B35: =SUMIF($B$2:$B$24,A35,$C$2:$C$24) -> 164.8 | C35: =B35/$C$25 -> 0.04006418
A36: Education | B36: =SUMIF($B$2:$B$24,A36,$C$2:$C$24) -> 177.1 | C36: =B36/$C$25 -> 0.043054408
A37: Total | C37: =SUM(C29:C36) -> 1
A40: Highest contributing bucket: | C40: =INDEX(A29:A36,MATCH(MAX(B29:B36),B29:B36,0)) -> Food

Sheet Q2 - YoY Trend
A1: Date | B1: YoY Inflation (General Index) | D1: Year | E1: Avg YoY Inflation
A2: ='YoY % Change'!A50 -> 42736 | B2: ='YoY % Change'!AE50 -> 0.031670625 | D2: 2017 | E2: =AVERAGEIFS($B$2:$B$78,$A$2:$A$78,">="&DATE(D2,1,1),$A$2:$A$78,"<="&DATE(D2,12,31)) -> 0.033273885
A3: ='YoY % Change'!A51 -> 42767 | B3: ='YoY % Change'!AE51 -> 0.036507937 | D3: 2018 | E3: =AVERAGEIFS($B$2:$B$78,$A$2:$A$78,">="&DATE(D3,1,1),$A$2:$A$78,"<="&DATE(D3,12,31)) -> 0.039676972
A4: ='YoY % Change'!A52 -> 42795 | B4: ='YoY % Change'!AE52 -> 0.038888889 | D4: 2019 | E4: =AVERAGEIFS($B$2:$B$78,$A$2:$A$78,">="&DATE(D4,1,1),$A$2:$A$78,"<="&DATE(D4,12,31)) -> 0.03705483
A5: ='YoY % Change'!A53 -> 42826 | B5: ='YoY % Change'!AE53 -> 0.029850746 | D5: 2020 | E5: =AVERAGEIFS($B$2:$B$78,$A$2:$A$78,">="&DATE(D5,1,1),$A$2:$A$78,"<="&DATE(D5,12,31)) -> 0.061994514
A6: ='YoY % Change'!A54 -> 42856 | B6: ='YoY % Change'!AE54 -> 0.021772939 | D6: 2021 | E6: =AVERAGEIFS($B$2:$B$78,$A$2:$A$78,">="&DATE(D6,1,1),$A$2:$A$78,"<="&DATE(D6,12,31)) -> 0.056349619
A7: ='YoY % Change'!A55 -> 42887 | B7: ='YoY % Change'!AE55 -> 0.014604151 | D7: 2022 | E7: =AVERAGEIFS($B$2:$B$78,$A$2:$A$78,">="&DATE(D7,1,1),$A$2:$A$78,"<="&DATE(D7,12,31)) -> 0.06624065
A8: ='YoY % Change'!A56 -> 42917 | B8: ='YoY % Change'!AE56 -> 0.023646072 | D8: 2023 | E8: =AVERAGEIFS($B$2:$B$78,$A$2:$A$78,">="&DATE(D8,1,1),$A$2:$A$78,"<="&DATE(D8,12,31)) -> 0.055756722
A9: ='YoY % Change'!A57 -> 42948 | B9: ='YoY % Change'!AE57 -> 0.03279939
A10: ='YoY % Change'!A58 -> 42979 | B10: ='YoY % Change'!AE58 -> 0.032849503
A11: ='YoY % Change'!A59 -> 43009 | B11: ='YoY % Change'!AE59 -> 0.035768645
A12: ='YoY % Change'!A60 -> 43040 | B12: ='YoY % Change'!AE60 -> 0.048780488
A13: ='YoY % Change'!A61 -> 43070 | B13: ='YoY % Change'!AE61 -> 0.052147239
A14: ='YoY % Change'!A62 -> 43101 | B14: ='YoY % Change'!AE62 -> 0.050652341
A15: ='YoY % Change'!A63 -> 43132 | B15: ='YoY % Change'!AE63 -> 0.044410413
A16: ='YoY % Change'!A64 -> 43160 | B16: ='YoY % Change'!AE64 -> 0.042780749
A17: ='YoY % Change'!A65 -> 43191 | B17: ='YoY % Change'!AE65 -> 0.04576659
A18: ='YoY % Change'!A66 -> 43221 | B18: ='YoY % Change'!AE66 -> 0.04870624
A19: ='YoY % Change'!A67 -> 43252 | B19: ='YoY % Change'!AE67 -> 0.049242424
A20: ='YoY % Change'!A68 -> 43282 | B20: ='YoY % Change'!AE68 -> 0.041728763
... A32: ='YoY % Change'!A80 -> 43647 | B32: ='YoY % Change'!AE80 -> 0.031473534
A33: ='YoY % Change'!A81 -> 43678 | B33: ='YoY % Change'!AE81 -> 0.032763533 | G33: *2022 recorded the highest average Y-o-Y inflation in this dataset (6.6%), driven primarily by a global commodity price shock. Russia's invasion of Ukraine in February 2022 disrupted global supply chains for crude oil, edible oils (India imports ~60% of its edible oil, much of it sunflower oil from the Black Sea region), wheat, and fertilizers. This pushed up international commodity prices sharply through mid-2022, and the Indian rupee's depreciation against the US dollar made imports costlier. The impact was most visible in Food and beverages, where inflation rose from an average of 4.4% in 2021 to 6.6% in 2022, led by cereals (from -0.7% to 8.0%), while edible oil prices stayed elevated early in the year. Overall CPI inflation stayed above the RBI's 6% upper tolerance band in 9 of the 12 months of 2022, and the RBI began a rate-hiking cycle in May 2022.
A34: ='YoY % Change'!A82 -> 43709 | B34: ='YoY % Change'!AE82 -> 0.039942939
A35: ='YoY % Change'!A83 -> 43739 | B35: ='YoY % Change'!AE83 -> 0.045454545 | E35: Highest inflation year
A36: ='YoY % Change'!A84 -> 43770 | B36: ='YoY % Change'!AE84 -> 0.055397727 | E36: =INDEX(D2:D8,MATCH(MAX(E2:E8),E2:E8,0)) -> 2022
A37: ='YoY % Change'!A85 -> 43800 | B37: ='YoY % Change'!AE85 -> 0.073518915
A38: ='YoY % Change'!A86 -> 43831 | B38: ='YoY % Change'!AE86 -> 0.075931232
A39: ='YoY % Change'!A87 -> 43862 | B39: ='YoY % Change'!AE87 -> 0.065761258
A40: ='YoY % Change'!A88 -> 43891 | B40: ='YoY % Change'!AE88 -> 0.058404558
A41: ='YoY % Change'!A89 -> 43922 | B41: ='YoY % Change'!AE89 -> 0.059962229
A42: ='YoY % Change'!A90 -> 43952 | B42: ='YoY % Change'!AE90 -> 0.061502347
A43: ='YoY % Change'!A91 -> 43983 | B43: ='YoY % Change'!AE91 -> 0.062281316
A44: ='YoY % Change'!A92 -> 44013 | B44: ='YoY % Change'!AE92 -> 0.052704577
A45: ='YoY % Change'!A93 -> 44044 | B45: ='YoY % Change'!AE93 -> 0.06137931
A46: ='YoY % Change'!A94 -> 44075 | B46: ='YoY % Change'!AE94 -> 0.061042524
A47: ='YoY % Change'!A95 -> 44105 | B47: ='YoY % Change'!AE95 -> 0.0625
A48: ='YoY % Change'!A96 -> 44136 | B48: ='YoY % Change'!AE96 -> 0.065948856
... A78: ='YoY % Change'!A126 -> 45047 | B78: ='YoY % Change'!AE126 -> 0.043098427

Sheet Q3 - Food Deep Dive
A1: Date | B1: Food MoM %
A2: ='MoM % Change'!A115 -> 44713 | B2: ='MoM % Change'!Q115 -> 0.0092325447
A3: ='MoM % Change'!A116 -> 44743 | B3: ='MoM % Change'!Q116 -> 0.00057175529
A4: ='MoM % Change'!A117 -> 44774 | B4: ='MoM % Change'!Q117 -> 0.0074285714
A5: ='MoM % Change'!A118 -> 44805 | B5: ='MoM % Change'!Q118 -> 0.0085082246
A6: ='MoM % Change'!A119 -> 44835 | B6: ='MoM % Change'!Q119 -> 0.010123735
A7: ='MoM % Change'!A120 -> 44866 | B7: ='MoM % Change'!Q120 -> -0.0072383073
A8: ='MoM % Change'!A121 -> 44896 | B8: ='MoM % Change'!Q121 -> -0.01346046
A9: ='MoM % Change'!A122 -> 44927 | B9: ='MoM % Change'!Q122 -> 0.0045480387
A10: ='MoM % Change'!A123 -> 44958 | B10: ='MoM % Change'!Q123 -> 0.0016977929
A11: ='MoM % Change'!A124 -> 44986 | B11: ='MoM % Change'!Q124 -> 0
A12: ='MoM % Change'!A125 -> 45017 | B12: ='MoM % Change'!Q125 -> 0.0050847458
A13: ='MoM % Change'!A126 -> 45047 | B13: ='MoM % Change'!Q126 -> 0.0067453626
A16: Sub-category | B16: Absolute Change (May'22 to May'23)
A17: Cereals and products | B17: ='Imputed Data'!E126-'Imputed Data'!E114 -> 19.6
A18: Meat and fish | B18: ='Imputed Data'!F126-'Imputed Data'!F114 -> -2.7
A19: Egg | B19: ='Imputed Data'!G126-'Imputed Data'!G114 -> 10.8
A20: Milk and products | B20: ='Imputed Data'!H126-'Imputed Data'!H114 -> 14.6
A21: Oils and fats | B21: ='Imputed Data'!I126-'Imputed Data'!I114 -> -32.4
A22: Fruits | B22: ='Imputed Data'!J126-'Imputed Data'!J114 -> 1.2
A23: Vegetables | B23: ='Imputed Data'!K126-'Imputed Data'!K114 -> -13.9 | F23: Values
A24: Pulses and products | B24: ='Imputed Data'!L126-'Imputed Data'!L114 -> 10.9 | D24: Highest Food Inflation Month | E24: =INDEX(A2:A13,MATCH(MAX(B2:B13),B2:B13,0)) -> 44835 | F24: =MAX(B2:B13) -> 0.010123735
A25: Sugar and Confectionery | B25: ='Imputed Data'!M126-'Imputed Data'!M114 -> 3 | D25: Lowest Food Inflation Month | E25: =INDEX(A2:A13,MATCH(MIN(B2:B13),B2:B13,0)) -> 44896 | F25: =MIN(B2:B13) -> -0.01346046
A26: Spices | B26: ='Imputed Data'!N126-'Imputed Data'!N114 -> 33.1 | D26: Absolute Change (Food Index) | E26: May 22 - 23 | F26: ='Imputed Data'!Q126-'Imputed Data'!Q114 -> 5.8
A27: Non-alcoholic beverages | B27: ='Imputed Data'!O126-'Imputed Data'!O114 -> 6.3 | D27: Biggest Driver Pushing Inflation Up | E27: =INDEX(A17:A28,MATCH(MAX(B17:B28),B17:B28,0)) -> Spices | F27: =MAX(Table18[Absolute Change (May''22 to May''23)]) -> 33.1
A28: Prepared meals etc. | B28: ='Imputed Data'!P126-'Imputed Data'!P114 -> 11.7 | D28: Biggest Driver Pushing Inflation Down | E28: =INDEX(A17:A28,MATCH(MIN(B17:B28),B17:B28,0)) -> Oils and fats | F28: =MIN(Table18[Absolute Change (May''22 to May''23)]) -> -32.4
A31: *Food inflation over the 12 months ending May 2023 peaked in October 2022 (+1.01% MoM) and bottomed out in December 2022 (-1.35% MoM), a pattern that may reflect India's seasonal harvest cycle, when post-monsoon arrivals of vegetables and cereals typically ease prices through the winter. Over the full window (May 2022 to May 2023), the Food and beverages index moved only +5.8 points net, even though individual items moved a lot. Spices rose the most (+33.1 points), possibly due to supply constraints, while Oils and fats fell the most (-32.4 points), likely as international edible oil prices, which spiked in 2022 after the Russia-Ukraine war (see Q2), eased through late 2022 and early 2023. Cereals (+19.6) and Milk and products (+14.6) also rose, while Vegetables fell (-13.9). Because the overall index is weighted by each item's share of the basket, large moves in single items do not translate one-for-one into the Food index, and aggregate indices can hide significant volatility underneath.

Sheet Q4 - COVID Impact
A1: Category | B1: Avg MoM % (Before: Mar'19-Feb'20) | C1: Avg MoM % (After: Mar'20-Feb'21) | D1: Change (pp) | I1: Date | J1: Health MoM% | K1: Food MoM% | L1: General Index MoM%
A2: Health | B2: =AVERAGE('MoM % Change'!Y76:Y87) -> 0.0034262997 | C2: =AVERAGE('MoM % Change'!Y88:Y99) -> 0.0051495311 | D2: =C2-B2 -> 0.0017232314 | I2: ='MoM % Change'!A86 -> 43831 | J2: ='MoM % Change'!Y86 -> 0.0053191489 | K2: ='MoM % Change'!Q86 -> -0.0096774194 | L2: ='MoM % Change'!AE86 -> -0.0013297872
A3: Food and beverages | B3: =AVERAGE('MoM % Change'!Q76:Q87) -> 0.0076173418 | C3: =AVERAGE('MoM % Change'!Q88:Q99) -> 0.0036052023 | D3: =C3-B3 -> -0.0040121395 | I3: ='MoM % Change'!A87 -> 43862 | J3: ='MoM % Change'!Y87 -> 0.0033068783 | K3: ='MoM % Change'!Q87 -> -0.019543974 | L3: ='MoM % Change'!AE87 -> -0.0073235686
A4: Transport and communication | B4: =AVERAGE('MoM % Change'!Z76:Z87) -> 0.0042321296 | C4: =AVERAGE('MoM % Change'!Z88:Z99) -> 0.0090428262 | D4: =C4-B4 -> 0.0048106966 | I4: ='MoM % Change'!A88 -> 43891 | J4: ='MoM % Change'!Y88 -> 0.0039551747 | K4: ='MoM % Change'!Q88 -> -0.010631229 | L4: ='MoM % Change'!AE88 -> -0.0033534541
A5: General index | B5: =AVERAGE('MoM % Change'!AE76:AE87) -> 0.0053342386 | C5: =AVERAGE('MoM % Change'!AE88:AE99) -> 0.0041228557 | D5: =C5-B5 -> -0.001211383 | I5: ='MoM % Change'!A89 -> 43922 | J5: ='MoM % Change'!Y89 -> -0.010505581 | K5: ='MoM % Change'!Q89 -> 0.016789792 | L5: ='MoM % Change'!AE89 -> 0.0071781068
I6: ='MoM % Change'!A90 -> 43952 | J6: ='MoM % Change'!Y90 -> 0.0199071 | K6: ='MoM % Change'!Q90 -> 0.0059445178 | L6: ='MoM % Change'!AE90 -> 0.0071269488
I7: ='MoM % Change'!A91 -> 43983 | J7: ='MoM % Change'!Y91 -> 0.0045543266 | K7: ='MoM % Change'!Q91 -> 0.01116218 | L7: ='MoM % Change'!AE91 -> 0.0070765148
I8: ='MoM % Change'!A92 -> 44013 | J8: ='MoM % Change'!Y92 -> 0 | K8: ='MoM % Change'!Q92 -> 0 | L8: ='MoM % Change'!AE92 -> 0
I9: ='MoM % Change'!A93 -> 44044 | J9: ='MoM % Change'!Y93 -> 0.0038860104 | K9: ='MoM % Change'!Q93 -> 0.019480519 | L9: ='MoM % Change'!AE93 -> 0.013833992
I10: ='MoM % Change'!A94 -> 44075 | J10: ='MoM % Change'!Y94 -> 0.0038709677 | K10: ='MoM % Change'!Q94 -> 0.0063694268 | L10: ='MoM % Change'!AE94 -> 0.0051981806
I11: ='MoM % Change'!A95 -> 44105 | J11: ='MoM % Change'!Y95 -> 0.0044987147 | K11: ='MoM % Change'!Q95 -> 0.021518987 | L11: ='MoM % Change'!AE95 -> 0.010989011
I12: ='MoM % Change'!A96 -> 44136 | J12: ='MoM % Change'!Y96 -> 0.0057581574 | K12: ='MoM % Change'!Q96 -> 0.020446097 | L12: ='MoM % Change'!AE96 -> 0.012787724
I13: ='MoM % Change'!A97 -> 44166 | J13: ='MoM % Change'!Y97 -> 0.0069974555 | K13: ='MoM % Change'!Q97 -> 0.0042501518 | L13: ='MoM % Change'!AE97 -> 0.0031565657
A29: *The "after" window includes April–May 2020, where May was missing for all categories and April for 13 of them (including General Index), so these values were estimated by linear interpolation between March and June 2020 due to MoSPI's lockdown-related data collection gap. Similarly, April 2019, which falls in the "before" window, was missing for all categories and was estimated as the midpoint of March and May 2019. Estimated values are, by construction, smoother than real reported data would have been, so they may understate true month-to-month volatility, especially during the strictest lockdown period. Additionally, June and July 2020 are identical across every category in the original government source. MoSPI appears to have carried forward June's figures as a placeholder for July, likely reflecting continued lockdown-related data collection disruption in several states. This means the "0% change" in July 2020 visible in the progression chart reflects a data-reporting gap, not genuine price stability.

Sheet Q5 - Oil Correlation
A1: Category | B1: Correlation with Oil MoM% | C1: Correlation
A2: Cereals and products | B2: =CORREL('Oil Price Data'!$C$3:$C$30,'MoM % Change'!E99:E126) -> -0.24805294 | C2: =ABS(B2) -> 0.24805294
A3: Meat and fish | B3: =CORREL('Oil Price Data'!$C$3:$C$30,'MoM % Change'!F99:F126) -> 0.44404115 | C3: =ABS(B3) -> 0.44404115
A4: Egg | B4: =CORREL('Oil Price Data'!$C$3:$C$30,'MoM % Change'!G99:G126) -> -0.17551886 | C4: =ABS(B4) -> 0.17551886
A5: Milk and products | B5: =CORREL('Oil Price Data'!$C$3:$C$30,'MoM % Change'!H99:H126) -> -0.27398891 | C5: =ABS(B5) -> 0.27398891
A6: Oils and fats | B6: =CORREL('Oil Price Data'!$C$3:$C$30,'MoM % Change'!I99:I126) -> 0.40288737 | C6: =ABS(B6) -> 0.40288737
A7: Fruits | B7: =CORREL('Oil Price Data'!$C$3:$C$30,'MoM % Change'!J99:J126) -> 0.086079961 | C7: =ABS(B7) -> 0.086079961
A8: Vegetables | B8: =CORREL('Oil Price Data'!$C$3:$C$30,'MoM % Change'!K99:K126) -> 0.030593198 | C8: =ABS(B8) -> 0.030593198
A9: Pulses and products | B9: =CORREL('Oil Price Data'!$C$3:$C$30,'MoM % Change'!L99:L126) -> -0.19229586 | C9: =ABS(B9) -> 0.19229586
A10: Sugar and Confectionery | B10: =CORREL('Oil Price Data'!$C$3:$C$30,'MoM % Change'!M99:M126) -> -0.18635779 | C10: =ABS(B10) -> 0.18635779
A11: Spices | B11: =CORREL('Oil Price Data'!$C$3:$C$30,'MoM % Change'!N99:N126) -> -0.14638647 | C11: =ABS(B11) -> 0.14638647
A12: Non-alcoholic beverages | B12: =CORREL('Oil Price Data'!$C$3:$C$30,'MoM % Change'!O99:O126) -> 0.14172258 | C12: =ABS(B12) -> 0.14172258
A13: Prepared meals, snacks, sweets etc. | B13: =CORREL('Oil Price Data'!$C$3:$C$30,'MoM % Change'!P99:P126) -> 0.059577525 | C13: =ABS(B13) -> 0.059577525
A14: Food and beverages | B14: =CORREL('Oil Price Data'!$C$3:$C$30,'MoM % Change'!Q99:Q126) -> 0.10585094 | C14: =ABS(B14) -> 0.10585094
A15: Pan, tobacco and intoxicants | B15: =CORREL('Oil Price Data'!$C$3:$C$30,'MoM % Change'!R99:R126) -> 0.15683405 | C15: =ABS(B15) -> 0.15683405
A16: Clothing | B16: =CORREL('Oil Price Data'!$C$3:$C$30,'MoM % Change'!S99:S126) -> 0.10340562 | C16: =ABS(B16) -> 0.10340562
A17: Footwear | B17: =CORREL('Oil Price Data'!$C$3:$C$30,'MoM % Change'!T99:T126) -> 0.17820951 | C17: =ABS(B17) -> 0.17820951
A18: Clothing and footwear | B18: =CORREL('Oil Price Data'!$C$3:$C$30,'MoM % Change'!U99:U126) -> 0.1221169 | C18: =ABS(B18) -> 0.1221169
A19: Housing | B19: =CORREL('Oil Price Data'!$C$3:$C$30,'MoM % Change'!V99:V126) -> 0.12963363 | C19: =ABS(B19) -> 0.12963363
A20: Fuel and light | B20: =CORREL('Oil Price Data'!$C$3:$C$30,'MoM % Change'!W99:W126) -> 0.094169945 | C20: =ABS(B20) -> 0.094169945
A21: Household goods and services | B21: =CORREL('Oil Price Data'!$C$3:$C$30,'MoM % Change'!X99:X126) -> 0.0027133749 | C21: =ABS(B21) -> 0.0027133749
A22: Health | B22: =CORREL('Oil Price Data'!$C$3:$C$30,'MoM % Change'!Y99:Y126) -> 0.058301361 | C22: =ABS(B22) -> 0.058301361
A23: Transport and communication | B23: =CORREL('Oil Price Data'!$C$3:$C$30,'MoM % Change'!Z99:Z126) -> 0.082848667 | C23: =ABS(B23) -> 0.082848667
A24: Recreation and amusement | B24: =CORREL('Oil Price Data'!$C$3:$C$30,'MoM % Change'!AA99:AA126) -> 0.10783717 | C24: =ABS(B24) -> 0.10783717
A25: Education | B25: =CORREL('Oil Price Data'!$C$3:$C$30,'MoM % Change'!AB99:AB126) -> -0.15087702 | C25: =ABS(B25) -> 0.15087702
A26: Personal care and effects | B26: =CORREL('Oil Price Data'!$C$3:$C$30,'MoM % Change'!AC99:AC126) -> 0.079638446 | C26: =ABS(B26) -> 0.079638446
A27: Miscellaneous | B27: =CORREL('Oil Price Data'!$C$3:$C$30,'MoM % Change'!AD99:AD126) -> 0.077950806 | C27: =ABS(B27) -> 0.077950806
A28: General index | B28: =CORREL('Oil Price Data'!$C$3:$C$30,'MoM % Change'!AE99:AE126) -> 0.12927341 | C28: =ABS(B28) -> 0.12927341
A31: Most correlated category | B31: =INDEX(A2:A28,MATCH(MAX(C2:C28),C2:C28,0)) -> Meat and fish
A32: Fuel and light correlation | B32: =B20 -> 0.094169945
A34: Contrary to the intuitive expectation, "Fuel and light" — the category most directly exposed to crude oil — shows almost no correlation with oil price changes (r = 0.09). This is because Indian retail fuel prices are heavily buffered by government policy rather than passed through directly: during this period, the Centre cut excise duty on petrol and diesel twice (November 2021 and May 2022) specifically to shield consumers from the full impact of record international crude prices, and public-sector oil marketing companies even absorbed losses rather than raise prices further — Indian Basket crude rose ~102% between Oct 2020 and Oct 2022, while retail petrol prices rose only ~19%. Instead, Meat and fish shows the strongest correlation (r = 0.44) — a moderate positive relationship likely driven by indirect exposure: rising fuel costs raise cold-chain logistics and animal feed costs (feed grains and edible oils track global commodity cycles), which feed into meat prices with more elasticity than the policy-dampened "Fuel and light" index does. This is a good example of why a policy-protected consumer price index doesn't always mirror the raw commodity driving it.

Sheet Cleaned Data
A1: Date | B1: Sector | C1: Year | D1: Month | E1: Cereals and products | F1: Meat and fish | G1: Egg | H1: Milk and products | I1: Oils and fats | J1: Fruits | K1: Vegetables | L1: Pulses and products | M1: Sugar and Confectionery | N1: Spices | O1: Non-alcoholic beverages | P1: Prepared meals, snacks, sweets etc. | Q1: Food and beverages | R1: Pan, tobacco and intoxicants | S1: Clothing | T1: Footwear | U1: Clothing and footwear | V1: Housing | W1: Fuel and light | X1: Household goods and services | Y1: Health | Z1: Transport and communication | AA1: Recreation and amusement | AB1: Education | AC1: Personal care and effects | AD1: Miscellaneous | AE1: General index
A2: 41275 | B2: Rural+Urban | C2: 2013 | D2: January | E2: 108.4 | F2: 107.3 | G2: 110 | H2: 104.4 | I2: 105.1 | J2: 103.2 | K2: 102.2 | L2: 106 | M2: 106.2 | N2: 102.7 | O2: 104.9 | P2: 107.3 | Q2: 105.6 | R2: 105.1 | S2: 106.3 | T2: 105.5 | U2: 106.2 | V2: 100.3 | W2: 105.5 | X2: 104.8 | Y2: 104 | Z2: 103.2 | AA2: 103.1 | AB2: 103.6 | AC2: 104.5 | AD2: 103.9 | AE2: 104.6
A3: 41306 | B3: Rural+Urban | C3: 2013 | D3: February | E3: 110.4 | F3: 110.2 | G3: 112.8 | H3: 104.9 | I3: 105.5 | J3: 103.6 | K3: 103.2 | L3: 105.3 | M3: 105.1 | N3: 102.8 | O3: 105.5 | P3: 108.3 | Q3: 106.6 | R3: 105.7 | S3: 106.9 | T3: 106 | U3: 106.8 | V3: 100.4 | W3: 106 | X3: 105.2 | Y3: 104.5 | Z3: 104.2 | AA3: 103.6 | AB3: 103.9 | AC3: 104.5 | AD3: 104.4 | AE3: 105.3
A4: 41334 | B4: Rural+Urban | C4: 2013 | D4: March | E4: 111.4 | F4: 109.7 | G4: 111.2 | H4: 105.1 | I4: 104.9 | J4: 105.3 | K4: 102.2 | L4: 105 | M4: 104.2 | N4: 103 | O4: 106.2 | P4: 108.9 | Q4: 106.9 | R4: 106.6 | S4: 107.4 | T4: 106.5 | U4: 107.3 | V4: 100.4 | W4: 106.1 | X4: 105.6 | Y4: 104.9 | Z4: 105.1 | AA4: 103.7 | AB4: 104 | AC4: 104.3 | AD4: 104.7 | AE4: 105.5
A5: 41365 | B5: Rural+Urban | C5: 2013 | D5: April | E5: 111.6 | F5: 110.9 | G5: 106.6 | H5: 105.7 | I5: 104.4 | J5: 108.9 | K5: 105.5 | L5: 105.3 | M5: 103.5 | N5: 103.3 | O5: 107.2 | P5: 109.6 | Q5: 107.7 | R5: 107.5 | S5: 108 | T5: 107 | U5: 107.9 | V5: 100.5 | W5: 106.5 | X5: 106.3 | Y5: 105.3 | Z5: 104.7 | AA5: 104.2 | AB5: 105 | AC5: 102.9 | AD5: 104.8 | AE5: 106.1
A6: 41395 | B6: Rural+Urban | C6: 2013 | D6: May | E6: 112.3 | F6: 111.3 | G6: 104.7 | H6: 106.8 | I6: 103.9 | J6: 109.3 | K6: 112.9 | L6: 105.8 | M6: 103.1 | N6: 104.3 | O6: 108.1 | P6: 110.5 | Q6: 109.2 | R6: 108.6 | S6: 108.7 | T6: 107.4 | U6: 108.5 | V6: 100.5 | W6: 107.4 | X6: 106.9 | Y6: 105.9 | Z6: 104 | AA6: 104.8 | AB6: 105.6 | AC6: 102.3 | AD6: 104.8 | AE6: 106.9
A7: 41426 | B7: Rural+Urban | C7: 2013 | D7: June | E7: 113.8 | F7: 114.9 | G7: 109.8 | H7: 107.9 | I7: 104.2 | J7: 110.7 | K7: 126.7 | L7: 106.3 | M7: 103.2 | N7: 105.7 | O7: 109 | P7: 111.6 | Q7: 112.2 | R7: 109.5 | S7: 109.5 | T7: 108.1 | U7: 109.3 | V7: 106.6 | W7: 108.3 | X7: 107.6 | Y7: 106.4 | Z7: 105.1 | AA7: 105.4 | AB7: 107.4 | AC7: 102.8 | AD7: 105.8 | AE7: 109.3
A8: 41456 | B8: Rural+Urban | C8: 2013 | D8: July | E8: 114.8 | F8: 116.4 | G8: 111.9 | H8: 108.9 | I8: 104.3 | J8: 111.7 | K8: 140 | L8: 106.4 | M8: 103.3 | N8: 106.8 | O8: 109.6 | P8: 112.6 | Q8: 114.7 | R8: 110.3 | S8: 110.2 | T8: 108.8 | U8: 110 | V8: 107.7 | W8: 109.2 | X8: 108.2 | Y8: 107 | Z8: 107.1 | AA8: 106.1 | AB8: 109.1 | AC8: 102.8 | AD8: 106.9 | AE8: 111
A9: 41487 | B9: Rural+Urban | C9: 2013 | D9: August | E9: 115.6 | F9: 117.2 | G9: 111.7 | H9: 109.6 | I9: 104.5 | J9: 109.8 | K9: 151.8 | L9: 106.5 | M9: 103.1 | N9: 107.4 | O9: 110.2 | P9: 113.4 | Q9: 116.6 | R9: 111.2 | S9: 111 | T9: 109.4 | U9: 110.7 | V9: 108.9 | W9: 109.7 | X9: 108.7 | Y9: 107.5 | Z9: 108 | AA9: 106.6 | AB9: 109.9 | AC9: 105.4 | AD9: 107.9 | AE9: 112.4
A10: 41518 | B10: Rural+Urban | C10: 2013 | D10: September | E10: 116.4 | F10: 116.9 | G10: 112.3 | H10: 110.5 | I10: 105.3 | J10: 107.3 | K10: 160.9 | L10: 107.1 | M10: 103.1 | N10: 108.3 | O10: 110.7 | P10: 114.6 | Q10: 118.3 | R10: 112 | S10: 112.2 | T10: 110.4 | U10: 111.9 | V10: 109.7 | W10: 110.5 | X10: 109.6 | Y10: 108.1 | Z10: 109.9 | AA10: 107.5 | AB10: 110.6 | AC10: 106.8 | AD10: 109 | AE10: 113.7
A11: 41548 | B11: Rural+Urban | C11: 2013 | D11: October | E11: 117.1 | F11: 116.3 | G11: 113.3 | H11: 111.2 | I11: 105.7 | J11: 109.9 | K11: 171.2 | L11: 107.3 | M11: 102.7 | N11: 108.7 | O11: 111.2 | P11: 115.4 | Q11: 120.2 | R11: 112.5 | S11: 113.2 | T11: 111.2 | U11: 112.8 | V11: 110.5 | W11: 110.9 | X11: 110.3 | Y11: 108.6 | Z11: 109.5 | AA11: 108.1 | AB11: 110.8 | AC11: 107.4 | AD11: 109.2 | AE11: 114.8
A12: 41579 | B12: Rural+Urban | C12: 2013 | D12: November | E12: 118.1 | F12: 115.4 | G12: 118.7 | H12: 112.5 | I12: 106.8 | J12: 113.5 | K12: 183.1 | L12: 108.2 | M12: 102.2 | N12: 109.4 | O12: 111.8 | P12: 116.5 | Q12: 122.6 | R12: 113.1 | S12: 114.2 | T12: 111.9 | U12: 113.8 | V12: 111.1 | W12: 111.6 | X12: 111.1 | Y12: 109.3 | Z12: 109.5 | AA12: 108.6 | AB12: 111.2 | AC12: 108.1 | AD12: 109.7 | AE12: 116.3
A13: 41609 | B13: Rural+Urban | C13: 2013 | D13: December | E13: 119.1 | F13: 116.7 | G13: 123.5 | H13: 113.4 | I13: 107.3 | J13: 113.3 | K13: 145.4 | L13: 108.7 | M13: 101.5 | N13: 110.5 | O13: 112.1 | P13: 117.4 | Q13: 118.4 | R13: 114 | S13: 115.2 | T13: 112.7 | U13: 114.8 | V13: 110.7 | W13: 111.9 | X13: 111.7 | Y13: 109.7 | Z13: 109.8 | AA13: 109 | AB13: 111.5 | AC13: 107.9 | AD13: 110 | AE13: 114.5
... A76: 43525 | B76: Rural+Urban | C76: 2019 | D76: March | E76: 137.8 | F76: 153 | G76: 140.3 | H76: 142.3 | I76: 122 | J76: 137.6 | K76: 132.6 | L76: 121.8 | M76: 109 | N76: 139.5 | O76: 133.7 | P76: 155.2 | Q76: 138.1 | R76: 163.5 | S76: 147.9 | T76: 139.9 | U76: 146.7 | V76: 149 | W76: 139.7 | X76: 143.8 | Y76: 146.2 | Z76: 124.6 | AA76: 137.7 | AB76: 150.3 | AC76: 133.4 | AD76: 137.7 | AE76: 140.4
A77: 43556 | B77: Rural+Urban | C77: 2019 | D77: April
A78: 43586 | B78: Rural+Urban | C78: 2019 | D78: May | E78: 138.3 | F78: 158.5 | G78: 136 | H78: 142.5 | I78: 122 | J78: 146.5 | K78: 143 | L78: 124.9 | M78: 109.9 | N78: 139.9 | O78: 134 | P78: 155.5 | Q78: 140.9 | R78: 164.1 | S78: 148.4 | T78: 140.4 | U78: 147.3 | V78: 150.1 | W78: 140.3 | X78: 143.7 | Y78: 146.9 | Z78: 124.9 | AA78: 139.2 | AB78: 151.6 | AC78: 133.4 | AD78: 138.2 | AE78: 142
A79: 43617 | B79: Rural+Urban | C79: 2019 | D79: June | E79: 138.7 | F79: 162.1 | G79: 137.8 | H79: 143.3 | I79: 122.2 | J79: 146.8 | K79: 150.5 | L79: 128.3 | M79: 111 | N79: 140.6 | O79: 134.2 | P79: 155.9 | Q79: 142.7 | R79: 164.9 | S79: 148.6 | T79: 140.4 | U79: 147.4 | V79: 149.4 | W79: 141.2 | X79: 143.8 | Y79: 147.4 | Z79: 124.6 | AA79: 139.6 | AB79: 152.5 | AC79: 134.3 | AD79: 138.6 | AE79: 142.9
A80: 43647 | B80: Rural+Urban | C80: 2019 | D80: July | E80: 139.3 | F80: 162.7 | G80: 140 | H80: 144 | I80: 122.5 | J80: 150.3 | K80: 160.3 | L80: 130 | M80: 111.1 | N80: 141.7 | O80: 134.7 | P80: 156.2 | Q80: 144.7 | R80: 165.2 | S80: 148.9 | T80: 140.5 | U80: 147.6 | V80: 150.6 | W80: 139.3 | X80: 144.2 | Y80: 147.9 | Z80: 125.6 | AA80: 140.5 | AB80: 154 | AC80: 135.7 | AD80: 139.5 | AE80: 144.2
A81: 43678 | B81: Rural+Urban | C81: 2019 | D81: August | E81: 140.1 | F81: 160.6 | G81: 138.5 | H81: 144.7 | I81: 122.9 | J81: 149.4 | K81: 167.4 | L81: 130.9 | M81: 112 | N81: 142.6 | O81: 134.9 | P81: 156.6 | Q81: 145.9 | R81: 165.8 | S81: 149.1 | T81: 140.6 | U81: 147.9 | V81: 151.6 | W81: 138.5 | X81: 144.5 | Y81: 148.5 | Z81: 125.8 | AA81: 140.9 | AB81: 154.9 | AC81: 138.4 | AD81: 140.2 | AE81: 145
A82: 43709 | B82: Rural+Urban | C82: 2019 | D82: September | E82: 140.9 | F82: 160.8 | G82: 139.6 | H82: 145.4 | I82: 123.5 | J82: 146.6 | K82: 173.2 | L82: 131.6 | M82: 113.2 | N82: 144.1 | O82: 135 | P82: 156.8 | Q82: 147 | R82: 166.5 | S82: 149.2 | T82: 140.6 | U82: 147.9 | V82: 152.2 | W82: 139.2 | X82: 144.6 | Y82: 149 | Z82: 126.1 | AA82: 141.3 | AB82: 155.2 | AC82: 139.7 | AD82: 140.7 | AE82: 145.8
A83: 43739 | B83: Rural+Urban | C83: 2019 | D83: October | E83: 141.8 | F83: 161 | G83: 142.6 | H83: 146.2 | I83: 123.9 | J83: 148 | K83: 188.4 | L83: 132.5 | M83: 114 | N83: 145.4 | O83: 135.1 | P83: 157.1 | Q83: 149.6 | R83: 167.1 | S83: 149.4 | T83: 140.8 | U83: 148.2 | V83: 153 | W83: 140.6 | X83: 145 | Y83: 149.4 | Z83: 126.3 | AA83: 141.7 | AB83: 155.4 | AC83: 140 | AD83: 141 | AE83: 147.2
A84: 43770 | B84: Rural+Urban | C84: 2019 | D84: November | E84: 142.5 | F84: 163.2 | G84: 145.6 | H84: 146.7 | I84: 124.3 | J84: 147.4 | K84: 199.6 | L84: 135.7 | M84: 114.2 | N84: 147 | O84: 135.3 | P84: 157.5 | Q84: 151.9 | R84: 167.9 | S84: 149.9 | T84: 141 | U84: 148.6 | V84: 153.5 | W84: 142.3 | X84: 145.3 | Y84: 149.9 | Z84: 126.6 | AA84: 142.1 | AB84: 155.5 | AC84: 140.3 | AD84: 141.3 | AE84: 148.6
A85: 43800 | B85: Rural+Urban | C85: 2019 | D85: December | E85: 143.5 | F85: 165 | G85: 151.1 | H85: 148.3 | I85: 125.7 | J85: 145.7 | K85: 217 | L85: 138.3 | M85: 114 | N85: 148.7 | O85: 135.8 | P85: 158 | Q85: 155 | R85: 168.5 | S85: 150.3 | T85: 141.3 | U85: 149 | V85: 152.8 | W85: 143.7 | X85: 145.8 | Y85: 150.4 | Z85: 129.8 | AA85: 142.3 | AB85: 155.7 | AC85: 140.4 | AD85: 142.5 | AE85: 150.4
A86: 43831 | B86: Rural+Urban | C86: 2020 | D86: January | E86: 144.3 | F86: 167.4 | G86: 154.9 | H86: 150.1 | I86: 129.9 | J86: 143.2 | K86: 197 | L86: 140.4 | M86: 114.1 | N86: 150.9 | O86: 136.1 | P86: 158.6 | Q86: 153.5 | R86: 169.2 | S86: 150.5 | T86: 141.5 | U86: 149.2 | V86: 153.9 | W86: 144.6 | X86: 146.2 | Y86: 151.2 | Z86: 130.9 | AA86: 142.8 | AB86: 156.1 | AC86: 142.3 | AD86: 143.4 | AE86: 150.2
A87: 43862 | B87: Rural+Urban | C87: 2020 | D87: February | E87: 144.8 | F87: 167.5 | G87: 151.8 | H87: 150.8 | I87: 131.4 | J87: 141.8 | K87: 170.7 | L87: 141.1 | M87: 113.6 | N87: 152 | O87: 136.5 | P87: 159.1 | Q87: 150.5 | R87: 170.1 | S87: 150.8 | T87: 141.7 | U87: 149.5 | V87: 154.8 | W87: 147.2 | X87: 146.4 | Y87: 151.7 | Z87: 130.3 | AA87: 143.2 | AB87: 156.2 | AC87: 143.4 | AD87: 143.6 | AE87: 149.1
A88: 43891 | B88: Rural+Urban | C88: 2020 | D88: March | E88: 145.1 | F88: 167 | G88: 148.1 | H88: 151.5 | I88: 131.2 | J88: 142.5 | K88: 157.3 | L88: 141.1 | M88: 113.2 | N88: 153.2 | O88: 136.7 | P88: 159.6 | Q88: 148.9 | R88: 171.2 | S88: 151.2 | T88: 141.9 | U88: 149.8 | V88: 154.5 | W88: 148.9 | X88: 146.4 | Y88: 152.3 | Z88: 129.9 | AA88: 143.7 | AB88: 156.1 | AC88: 145.2 | AD88: 143.8 | AE88: 148.6
A89: 43922 | B89: Rural+Urban | C89: 2020 | D89: April | E89: 148.7 | G89: 148.8 | H89: 155.6 | I89: 135.1 | J89: 149.9 | K89: 168.6 | L89: 150.4 | M89: 120.3 | N89: 157.1 | O89: 136.8 | Q89: 151.4 | V89: 155.6 | W89: 144.1 | Y89: 150.7
A90: 43952 | B90: Rural+Urban | C90: 2020 | D90: May
A91: 43983 | B91: Rural+Urban | C91: 2020 | D91: June | E91: 149.6 | F91: 192.7 | G91: 151.4 | H91: 153.3 | I91: 136.3 | J91: 147.2 | K91: 156.5 | L91: 150.9 | M91: 114.2 | N91: 159.5 | O91: 139.4 | P91: 161.8 | Q91: 154 | R91: 183.5 | S91: 152.5 | T91: 144.4 | U91: 151.4 | V91: 154.7 | W91: 141.9 | X91: 146.4 | Y91: 154.4 | Z91: 135 | AA91: 148.3 | AB91: 156.4 | AC91: 151.6 | AD91: 147 | AE91: 151.8
A92: 44013 | B92: Rural+Urban | C92: 2020 | D92: July | E92: 149.6 | F92: 192.7 | G92: 151.4 | H92: 153.3 | I92: 136.3 | J92: 147.2 | K92: 156.5 | L92: 150.9 | M92: 114.2 | N92: 159.5 | O92: 139.4 | P92: 161.8 | Q92: 154 | R92: 183.5 | S92: 152.5 | T92: 144.4 | U92: 151.4 | V92: 154.7 | W92: 141.9 | X92: 146.4 | Y92: 154.4 | Z92: 135 | AA92: 148.3 | AB92: 156.4 | AC92: 151.6 | AD92: 147 | AE92: 151.8
A93: 44044 | B93: Rural+Urban | C93: 2020 | D93: August | E93: 148.9 | F93: 190.9 | G93: 150.8 | H93: 153.3 | I93: 137.4 | J93: 150.4 | K93: 178.1 | L93: 150.4 | M93: 115.1 | N93: 160 | O93: 140.6 | P93: 162.3 | Q93: 157 | R93: 182.6 | S93: 153.1 | T93: 143.4 | U93: 151.7 | V93: 155.5 | W93: 143 | X93: 148.4 | Y93: 155 | Z93: 138.5 | AA93: 146 | AB93: 158.5 | AC93: 154.3 | AD93: 149 | AE93: 153.9
A94: 44075 | B94: Rural+Urban | C94: 2020 | D94: September | E94: 148.4 | F94: 187.1 | G94: 152.5 | H94: 153.6 | I94: 138.2 | J94: 150.9 | K94: 186.7 | L94: 149.8 | M94: 116.4 | N94: 160.3 | O94: 142.2 | P94: 162.9 | Q94: 158 | R94: 184.4 | S94: 153.4 | T94: 144.3 | U94: 152 | V94: 156.3 | W94: 142.9 | X94: 148.7 | Y94: 155.6 | Z94: 139.6 | AA94: 146.6 | AB94: 157.5 | AC94: 158.4 | AD94: 150 | AE94: 154.7
A95: 44105 | B95: Rural+Urban | C95: 2020 | D95: October | E95: 147.5 | F95: 188.9 | G95: 161.4 | H95: 153.6 | I95: 140.1 | J95: 151.2 | K95: 209.2 | L95: 150.9 | M95: 116.2 | N95: 161 | O95: 144 | P95: 163.2 | Q95: 161.4 | R95: 184.3 | S95: 153.7 | T95: 144.6 | U95: 152.3 | V95: 156.5 | W95: 143.1 | X95: 148.7 | Y95: 156.3 | Z95: 140.6 | AA95: 146.5 | AB95: 158.5 | AC95: 157 | AD95: 150.4 | AE95: 156.4
A96: 44136 | B96: Rural+Urban | C96: 2020 | D96: November | E96: 146.8 | F96: 191 | G96: 173.6 | H96: 153.8 | I96: 142.7 | J96: 148.4 | K96: 230 | L96: 156.8 | M96: 115.7 | N96: 161.8 | O96: 146.5 | P96: 163.8 | Q96: 164.7 | R96: 184.8 | S96: 154.3 | T96: 144.9 | U96: 152.8 | V96: 158 | W96: 143.6 | X96: 149.2 | Y96: 157.2 | Z96: 140.4 | AA96: 148.4 | AB96: 158.6 | AC96: 156.9 | AD96: 150.7 | AE96: 158.4
A97: 44166 | B97: Rural+Urban | C97: 2020 | D97: December | E97: 146 | F97: 191 | G97: 175.3 | H97: 154.1 | I97: 146.6 | J97: 147.7 | K97: 230.5 | L97: 160.2 | M97: 115.3 | N97: 163 | O97: 149.2 | P97: 164.8 | Q97: 165.4 | R97: 185.4 | S97: 155 | T97: 145.4 | U97: 153.6 | V97: 158.4 | W97: 144.6 | X97: 149.7 | Y97: 158.3 | Z97: 140.7 | AA97: 148.5 | AB97: 159.4 | AC97: 157.1 | AD97: 151.2 | AE97: 158.9
A98: 44197 | B98: Rural+Urban | C98: 2021 | D98: January | E98: 144.9 | F98: 190.1 | G98: 175.3 | H98: 154.1 | I98: 150.9 | J98: 149.6 | K98: 194.2 | L98: 160.4 | M98: 114.6 | N98: 164 | O98: 151.8 | P98: 165.6 | Q98: 161 | R98: 186.5 | S98: 155.5 | T98: 146.1 | U98: 154.2 | V98: 157.7 | W98: 147.9 | X98: 150 | Y98: 159.3 | Z98: 141.9 | AA98: 149.6 | AB98: 159.2 | AC98: 156.8 | AD98: 151.9 | AE98: 157.3
A99: 44228 | B99: Rural+Urban | C99: 2021 | D99: February | E99: 144.3 | F99: 186.5 | G99: 168.7 | H99: 154.7 | I99: 158.7 | J99: 150.7 | K99: 160 | L99: 158.8 | M99: 112.8 | N99: 164.2 | O99: 155.5 | P99: 167.5 | Q99: 156.9 | R99: 188.3 | S99: 157.2 | T99: 147.4 | U99: 155.8 | V99: 159.8 | W99: 152.4 | X99: 150.9 | Y99: 161.3 | Z99: 145.1 | AA99: 151.5 | AB99: 159.5 | AC99: 155.8 | AD99: 153.4 | AE99: 156.6
A100: 44256 | B100: Rural+Urban | C100: 2021 | D100: March | E100: 144.1 | F100: 192.2 | G100: 163.8 | H100: 154.9 | I100: 163.9 | J100: 153.7 | K100: 149.5 | L100: 159.8 | M100: 112.6 | N100: 163.5 | O100: 156.5 | P100: 168.2 | Q100: 156.7 | R100: 188.1 | S100: 157.8 | T100: 147.9 | U100: 156.4 | V100: 159.9 | W100: 155.5 | X100: 151.2 | Y100: 161.7 | Z100: 146.2 | AA100: 152.6 | AB100: 160.2 | AC100: 153.8 | AD100: 153.8 | AE100: 156.8
A101: 44287 | B101: Rural+Urban | C101: 2021 | D101: April | E101: 144.3 | F101: 198 | G101: 164.6 | H101: 155.4 | I101: 170.1 | J101: 164.4 | K101: 144.1 | L101: 161.7 | M101: 113.1 | N101: 163.9 | O101: 157.6 | P101: 168.9 | Q101: 158 | R101: 188.8 | S101: 158.8 | T101: 148.5 | U101: 157.3 | V101: 161.4 | W101: 155.6 | X101: 151.8 | Y101: 162.3 | Z101: 146.6 | AA101: 153.2 | AB101: 160.3 | AC101: 155.4 | AD101: 154.4 | AE101: 157.8
A102: 44317 | B102: Rural+Urban | C102: 2021 | D102: May | E102: 146.3 | F102: 200.5 | G102: 170.3 | H102: 156.1 | I102: 178.7 | J102: 167.1 | K102: 147.9 | L102: 165.4 | M102: 114.8 | N102: 168.2 | O102: 159.3 | P102: 170.4 | Q102: 160.7 | R102: 191.9 | S102: 161.8 | T102: 152.1 | U102: 160.4 | V102: 161.6 | W102: 159.4 | X102: 154.7 | Y102: 165.8 | Z102: 148.9 | AA102: 155.8 | AB102: 161.2 | AC102: 158.6 | AD102: 156.8 | AE102: 160.4
...

Sheet Imputed Data
A1: Date | B1: Sector | C1: Year | D1: Month | E1: Cereals and products | F1: Meat and fish | G1: Egg | H1: Milk and products | I1: Oils and fats | J1: Fruits | K1: Vegetables | L1: Pulses and products | M1: Sugar and Confectionery | N1: Spices | O1: Non-alcoholic beverages | P1: Prepared meals, snacks, sweets etc. | Q1: Food and beverages | R1: Pan, tobacco and intoxicants | S1: Clothing | T1: Footwear | U1: Clothing and footwear | V1: Housing | W1: Fuel and light | X1: Household goods and services | Y1: Health | Z1: Transport and communication | AA1: Recreation and amusement | AB1: Education | AC1: Personal care and effects | AD1: Miscellaneous | AE1: General index
A2: ='Cleaned Data'!A2 -> 41275 | B2: ='Cleaned Data'!B2 -> Rural+Urban | C2: ='Cleaned Data'!C2 -> 2013 | D2: ='Cleaned Data'!D2 -> January | E2: ='Cleaned Data'!E2 -> 108.4 | F2: ='Cleaned Data'!F2 -> 107.3 | G2: ='Cleaned Data'!G2 -> 110 | H2: ='Cleaned Data'!H2 -> 104.4 | ... AE2: ='Cleaned Data'!AE2 -> 104.6
A3: ='Cleaned Data'!A3 -> 41306 | B3: ='Cleaned Data'!B3 -> Rural+Urban | C3: ='Cleaned Data'!C3 -> 2013 | D3: ='Cleaned Data'!D3 -> February | E3: ='Cleaned Data'!E3 -> 110.4 | F3: ='Cleaned Data'!F3 -> 110.2 | G3: ='Cleaned Data'!G3 -> 112.8 | H3: ='Cleaned Data'!H3 -> 104.9 | ... AE3: ='Cleaned Data'!AE3 -> 105.3
A4: ='Cleaned Data'!A4 -> 41334 | B4: ='Cleaned Data'!B4 -> Rural+Urban | C4: ='Cleaned Data'!C4 -> 2013 | D4: ='Cleaned Data'!D4 -> March | E4: ='Cleaned Data'!E4 -> 111.4 | F4: ='Cleaned Data'!F4 -> 109.7 | G4: ='Cleaned Data'!G4 -> 111.2 | H4: ='Cleaned Data'!H4 -> 105.1 | ... AE4: ='Cleaned Data'!AE4 -> 105.5
A5: ='Cleaned Data'!A5 -> 41365 | B5: ='Cleaned Data'!B5 -> Rural+Urban | C5: ='Cleaned Data'!C5 -> 2013 | D5: ='Cleaned Data'!D5 -> April | E5: ='Cleaned Data'!E5 -> 111.6 | F5: ='Cleaned Data'!F5 -> 110.9 | G5: ='Cleaned Data'!G5 -> 106.6 | H5: ='Cleaned Data'!H5 -> 105.7 | ... AE5: ='Cleaned Data'!AE5 -> 106.1
A6: ='Cleaned Data'!A6 -> 41395 | B6: ='Cleaned Data'!B6 -> Rural+Urban | C6: ='Cleaned Data'!C6 -> 2013 | D6: ='Cleaned Data'!D6 -> May | E6: ='Cleaned Data'!E6 -> 112.3 | F6: ='Cleaned Data'!F6 -> 111.3 | G6: ='Cleaned Data'!G6 -> 104.7 | H6: ='Cleaned Data'!H6 -> 106.8 | ... AE6: ='Cleaned Data'!AE6 -> 106.9
A7: ='Cleaned Data'!A7 -> 41426 | B7: ='Cleaned Data'!B7 -> Rural+Urban | C7: ='Cleaned Data'!C7 -> 2013 | D7: ='Cleaned Data'!D7 -> June | E7: ='Cleaned Data'!E7 -> 113.8 | F7: ='Cleaned Data'!F7 -> 114.9 | G7: ='Cleaned Data'!G7 -> 109.8 | H7: ='Cleaned Data'!H7 -> 107.9 | ... AE7: ='Cleaned Data'!AE7 -> 109.3
A8: ='Cleaned Data'!A8 -> 41456 | B8: ='Cleaned Data'!B8 -> Rural+Urban | C8: ='Cleaned Data'!C8 -> 2013 | D8: ='Cleaned Data'!D8 -> July | E8: ='Cleaned Data'!E8 -> 114.8 | F8: ='Cleaned Data'!F8 -> 116.4 | G8: ='Cleaned Data'!G8 -> 111.9 | H8: ='Cleaned Data'!H8 -> 108.9 | ... AE8: ='Cleaned Data'!AE8 -> 111
A9: ='Cleaned Data'!A9 -> 41487 | B9: ='Cleaned Data'!B9 -> Rural+Urban | C9: ='Cleaned Data'!C9 -> 2013 | D9: ='Cleaned Data'!D9 -> August | E9: ='Cleaned Data'!E9 -> 115.6 | F9: ='Cleaned Data'!F9 -> 117.2 | G9: ='Cleaned Data'!G9 -> 111.7 | H9: ='Cleaned Data'!H9 -> 109.6 | ... AE9: ='Cleaned Data'!AE9 -> 112.4
A10: ='Cleaned Data'!A10 -> 41518 | B10: ='Cleaned Data'!B10 -> Rural+Urban | C10: ='Cleaned Data'!C10 -> 2013 | D10: ='Cleaned Data'!D10 -> September | E10: ='Cleaned Data'!E10 -> 116.4 | F10: ='Cleaned Data'!F10 -> 116.9 | G10: ='Cleaned Data'!G10 -> 112.3 | H10: ='Cleaned Data'!H10 -> 110.5 | ... AE10: ='Cleaned Data'!AE10 -> 113.7
A11: ='Cleaned Data'!A11 -> 41548 | B11: ='Cleaned Data'!B11 -> Rural+Urban | C11: ='Cleaned Data'!C11 -> 2013 | D11: ='Cleaned Data'!D11 -> October | E11: ='Cleaned Data'!E11 -> 117.1 | F11: ='Cleaned Data'!F11 -> 116.3 | G11: ='Cleaned Data'!G11 -> 113.3 | H11: ='Cleaned Data'!H11 -> 111.2 | ... AE11: ='Cleaned Data'!AE11 -> 114.8
A12: ='Cleaned Data'!A12 -> 41579 | B12: ='Cleaned Data'!B12 -> Rural+Urban | C12: ='Cleaned Data'!C12 -> 2013 | D12: ='Cleaned Data'!D12 -> November | E12: ='Cleaned Data'!E12 -> 118.1 | F12: ='Cleaned Data'!F12 -> 115.4 | G12: ='Cleaned Data'!G12 -> 118.7 | H12: ='Cleaned Data'!H12 -> 112.5 | ... AE12: ='Cleaned Data'!AE12 -> 116.3
A13: ='Cleaned Data'!A13 -> 41609 | B13: ='Cleaned Data'!B13 -> Rural+Urban | C13: ='Cleaned Data'!C13 -> 2013 | D13: ='Cleaned Data'!D13 -> December | E13: ='Cleaned Data'!E13 -> 119.1 | F13: ='Cleaned Data'!F13 -> 116.7 | G13: ='Cleaned Data'!G13 -> 123.5 | H13: ='Cleaned Data'!H13 -> 113.4 | ... AE13: ='Cleaned Data'!AE13 -> 114.5
... A76: ='Cleaned Data'!A76 -> 43525 | B76: ='Cleaned Data'!B76 -> Rural+Urban | C76: ='Cleaned Data'!C76 -> 2019 | D76: ='Cleaned Data'!D76 -> March | E76: ='Cleaned Data'!E76 -> 137.8 | F76: ='Cleaned Data'!F76 -> 153 | G76: ='Cleaned Data'!G76 -> 140.3 | H76: ='Cleaned Data'!H76 -> 142.3 | ... AE76: ='Cleaned Data'!AE76 -> 140.4
A77: ='Cleaned Data'!A77 -> 43556 | B77: ='Cleaned Data'!B77 -> Rural+Urban | C77: ='Cleaned Data'!C77 -> 2019 | D77: ='Cleaned Data'!D77 -> April | E77: 138.05 | F77: 155.75 | G77: 138.15 | H77: 142.4 | I77: 122 | J77: 142.05 | K77: 137.8 | L77: 123.35 | M77: 109.45 | N77: 139.7 | O77: 133.85 | P77: 155.35 | Q77: 139.5 | R77: 163.8 | S77: 148.15 | T77: 140.15 | U77: 147 | V77: 149.55 | W77: 140 | X77: 143.75 | Y77: 146.55 | Z77: 124.75 | AA77: 138.45 | AB77: 150.95 | AC77: 133.4 | AD77: 137.95 | AE77: 141.2
A78: ='Cleaned Data'!A78 -> 43586 | B78: ='Cleaned Data'!B78 -> Rural+Urban | C78: ='Cleaned Data'!C78 -> 2019 | D78: ='Cleaned Data'!D78 -> May | E78: ='Cleaned Data'!E78 -> 138.3 | F78: ='Cleaned Data'!F78 -> 158.5 | G78: ='Cleaned Data'!G78 -> 136 | H78: ='Cleaned Data'!H78 -> 142.5 | ... AE78: ='Cleaned Data'!AE78 -> 142
A79: ='Cleaned Data'!A79 -> 43617 | B79: ='Cleaned Data'!B79 -> Rural+Urban | C79: ='Cleaned Data'!C79 -> 2019 | D79: ='Cleaned Data'!D79 -> June | E79: ='Cleaned Data'!E79 -> 138.7 | F79: ='Cleaned Data'!F79 -> 162.1 | G79: ='Cleaned Data'!G79 -> 137.8 | H79: ='Cleaned Data'!H79 -> 143.3 | ... AE79: ='Cleaned Data'!AE79 -> 142.9
A80: ='Cleaned Data'!A80 -> 43647 | B80: ='Cleaned Data'!B80 -> Rural+Urban | C80: ='Cleaned Data'!C80 -> 2019 | D80: ='Cleaned Data'!D80 -> July | E80: ='Cleaned Data'!E80 -> 139.3 | F80: ='Cleaned Data'!F80 -> 162.7 | G80: ='Cleaned Data'!G80 -> 140 | H80: ='Cleaned Data'!H80 -> 144 | ... AE80: ='Cleaned Data'!AE80 -> 144.2
A81: ='Cleaned Data'!A81 -> 43678 | B81: ='Cleaned Data'!B81 -> Rural+Urban | C81: ='Cleaned Data'!C81 -> 2019 | D81: ='Cleaned Data'!D81 -> August | E81: ='Cleaned Data'!E81 -> 140.1 | F81: ='Cleaned Data'!F81 -> 160.6 | G81: ='Cleaned Data'!G81 -> 138.5 | H81: ='Cleaned Data'!H81 -> 144.7 | ... AE81: ='Cleaned Data'!AE81 -> 145
A82: ='Cleaned Data'!A82 -> 43709 | B82: ='Cleaned Data'!B82 -> Rural+Urban | C82: ='Cleaned Data'!C82 -> 2019 | D82: ='Cleaned Data'!D82 -> September | E82: ='Cleaned Data'!E82 -> 140.9 | F82: ='Cleaned Data'!F82 -> 160.8 | G82: ='Cleaned Data'!G82 -> 139.6 | H82: ='Cleaned Data'!H82 -> 145.4 | ... AE82: ='Cleaned Data'!AE82 -> 145.8
A83: ='Cleaned Data'!A83 -> 43739 | B83: ='Cleaned Data'!B83 -> Rural+Urban | C83: ='Cleaned Data'!C83 -> 2019 | D83: ='Cleaned Data'!D83 -> October | E83: ='Cleaned Data'!E83 -> 141.8 | F83: ='Cleaned Data'!F83 -> 161 | G83: ='Cleaned Data'!G83 -> 142.6 | H83: ='Cleaned Data'!H83 -> 146.2 | ... AE83: ='Cleaned Data'!AE83 -> 147.2
A84: ='Cleaned Data'!A84 -> 43770 | B84: ='Cleaned Data'!B84 -> Rural+Urban | C84: ='Cleaned Data'!C84 -> 2019 | D84: ='Cleaned Data'!D84 -> November | E84: ='Cleaned Data'!E84 -> 142.5 | F84: ='Cleaned Data'!F84 -> 163.2 | G84: ='Cleaned Data'!G84 -> 145.6 | H84: ='Cleaned Data'!H84 -> 146.7 | ... AE84: ='Cleaned Data'!AE84 -> 148.6
A85: ='Cleaned Data'!A85 -> 43800 | B85: ='Cleaned Data'!B85 -> Rural+Urban | C85: ='Cleaned Data'!C85 -> 2019 | D85: ='Cleaned Data'!D85 -> December | E85: ='Cleaned Data'!E85 -> 143.5 | F85: ='Cleaned Data'!F85 -> 165 | G85: ='Cleaned Data'!G85 -> 151.1 | H85: ='Cleaned Data'!H85 -> 148.3 | ... AE85: ='Cleaned Data'!AE85 -> 150.4
A86: ='Cleaned Data'!A86 -> 43831 | B86: ='Cleaned Data'!B86 -> Rural+Urban | C86: ='Cleaned Data'!C86 -> 2020 | D86: ='Cleaned Data'!D86 -> January | E86: ='Cleaned Data'!E86 -> 144.3 | F86: ='Cleaned Data'!F86 -> 167.4 | G86: ='Cleaned Data'!G86 -> 154.9 | H86: ='Cleaned Data'!H86 -> 150.1 | ... AE86: ='Cleaned Data'!AE86 -> 150.2
A87: ='Cleaned Data'!A87 -> 43862 | B87: ='Cleaned Data'!B87 -> Rural+Urban | C87: ='Cleaned Data'!C87 -> 2020 | D87: ='Cleaned Data'!D87 -> February | E87: ='Cleaned Data'!E87 -> 144.8 | F87: ='Cleaned Data'!F87 -> 167.5 | G87: ='Cleaned Data'!G87 -> 151.8 | H87: ='Cleaned Data'!H87 -> 150.8 | ... AE87: ='Cleaned Data'!AE87 -> 149.1
A88: ='Cleaned Data'!A88 -> 43891 | B88: ='Cleaned Data'!B88 -> Rural+Urban | C88: ='Cleaned Data'!C88 -> 2020 | D88: ='Cleaned Data'!D88 -> March | E88: ='Cleaned Data'!E88 -> 145.1 | F88: ='Cleaned Data'!F88 -> 167 | G88: ='Cleaned Data'!G88 -> 148.1 | H88: ='Cleaned Data'!H88 -> 151.5 | ... AE88: ='Cleaned Data'!AE88 -> 148.6
A89: ='Cleaned Data'!A89 -> 43922 | B89: ='Cleaned Data'!B89 -> Rural+Urban | C89: ='Cleaned Data'!C89 -> 2020 | D89: ='Cleaned Data'!D89 -> April | E89: ='Cleaned Data'!E89 -> 148.7 | F89: 175.56667 | G89: ='Cleaned Data'!G89 -> 148.8 | H89: ='Cleaned Data'!H89 -> 155.6 | I89: ='Cleaned Data'!I89 -> 135.1 | J89: ='Cleaned Data'!J89 -> 149.9 | K89: ='Cleaned Data'!K89 -> 168.6 | L89: ='Cleaned Data'!L89 -> 150.4 | M89: ='Cleaned Data'!M89 -> 120.3 | N89: ='Cleaned Data'!N89 -> 157.1 | O89: ='Cleaned Data'!O89 -> 136.8 | P89: 160.33333 | Q89: ='Cleaned Data'!Q89 -> 151.4 | R89: 175.3 | S89: 151.63333 | T89: 142.73333 | U89: 150.33333 | V89: ='Cleaned Data'!V89 -> 155.6 | W89: ='Cleaned Data'!W89 -> 144.1 | X89: 146.4 | Y89: ='Cleaned Data'!Y89 -> 150.7 | Z89: 131.6 | AA89: 145.23333 | AB89: 156.2 | AC89: 147.33333 | AD89: 144.86667 | AE89: 149.66667
A90: ='Cleaned Data'!A90 -> 43952 | B90: ='Cleaned Data'!B90 -> Rural+Urban | C90: ='Cleaned Data'!C90 -> 2020 | D90: ='Cleaned Data'!D90 -> May | E90: 148.1 | F90: 184.13333 | G90: 150.3 | H90: 152.7 | I90: 134.6 | J90: 145.63333 | K90: 156.76667 | L90: 147.63333 | M90: 113.86667 | N90: 157.4 | O90: 138.5 | P90: 161.06667 | Q90: 152.3 | R90: 179.4 | S90: 152.06667 | T90: 143.56667 | U90: 150.86667 | V90: 154.63333 | W90: 144.23333 | X90: 146.4 | Y90: 153.7 | Z90: 133.3 | AA90: 146.76667 | AB90: 156.3 | AC90: 149.46667 | AD90: 145.93333 | AE90: 150.73333
A91: ='Cleaned Data'!A91 -> 43983 | B91: ='Cleaned Data'!B91 -> Rural+Urban | C91: ='Cleaned Data'!C91 -> 2020 | D91: ='Cleaned Data'!D91 -> June | E91: ='Cleaned Data'!E91 -> 149.6 | F91: ='Cleaned Data'!F91 -> 192.7 | G91: ='Cleaned Data'!G91 -> 151.4 | H91: ='Cleaned Data'!H91 -> 153.3 | ... AE91: ='Cleaned Data'!AE91 -> 151.8
A92: ='Cleaned Data'!A92 -> 44013 | B92: ='Cleaned Data'!B92 -> Rural+Urban | C92: ='Cleaned Data'!C92 -> 2020 | D92: ='Cleaned Data'!D92 -> July | E92: ='Cleaned Data'!E92 -> 149.6 | F92: ='Cleaned Data'!F92 -> 192.7 | G92: ='Cleaned Data'!G92 -> 151.4 | H92: ='Cleaned Data'!H92 -> 153.3 | ... AE92: ='Cleaned Data'!AE92 -> 151.8
A93: ='Cleaned Data'!A93 -> 44044 | B93: ='Cleaned Data'!B93 -> Rural+Urban | C93: ='Cleaned Data'!C93 -> 2020 | D93: ='Cleaned Data'!D93 -> August | E93: ='Cleaned Data'!E93 -> 148.9 | F93: ='Cleaned Data'!F93 -> 190.9 | G93: ='Cleaned Data'!G93 -> 150.8 | H93: ='Cleaned Data'!H93 -> 153.3 | ... AE93: ='Cleaned Data'!AE93 -> 153.9
A94: ='Cleaned Data'!A94 -> 44075 | B94: ='Cleaned Data'!B94 -> Rural+Urban | C94: ='Cleaned Data'!C94 -> 2020 | D94: ='Cleaned Data'!D94 -> September | E94: ='Cleaned Data'!E94 -> 148.4 | F94: ='Cleaned Data'!F94 -> 187.1 | G94: ='Cleaned Data'!G94 -> 152.5 | H94: ='Cleaned Data'!H94 -> 153.6 | ... AE94: ='Cleaned Data'!AE94 -> 154.7
A95: ='Cleaned Data'!A95 -> 44105 | B95: ='Cleaned Data'!B95 -> Rural+Urban | C95: ='Cleaned Data'!C95 -> 2020 | D95: ='Cleaned Data'!D95 -> October | E95: ='Cleaned Data'!E95 -> 147.5 | F95: ='Cleaned Data'!F95 -> 188.9 | G95: ='Cleaned Data'!G95 -> 161.4 | H95: ='Cleaned Data'!H95 -> 153.6 | ... AE95: ='Cleaned Data'!AE95 -> 156.4
A96: ='Cleaned Data'!A96 -> 44136 | B96: ='Cleaned Data'!B96 -> Rural+Urban | C96: ='Cleaned Data'!C96 -> 2020 | D96: ='Cleaned Data'!D96 -> November | E96: ='Cleaned Data'!E96 -> 146.8 | F96: ='Cleaned Data'!F96 -> 191 | G96: ='Cleaned Data'!G96 -> 173.6 | H96: ='Cleaned Data'!H96 -> 153.8 | ... AE96: ='Cleaned Data'!AE96 -> 158.4
A97: ='Cleaned Data'!A97 -> 44166 | B97: ='Cleaned Data'!B97 -> Rural+Urban | C97: ='Cleaned Data'!C97 -> 2020 | D97: ='Cleaned Data'!D97 -> December | E97: ='Cleaned Data'!E97 -> 146 | F97: ='Cleaned Data'!F97 -> 191 | G97: ='Cleaned Data'!G97 -> 175.3 | H97: ='Cleaned Data'!H97 -> 154.1 | ... AE97: ='Cleaned Data'!AE97 -> 158.9
A98: ='Cleaned Data'!A98 -> 44197 | B98: ='Cleaned Data'!B98 -> Rural+Urban | C98: ='Cleaned Data'!C98 -> 2021 | D98: ='Cleaned Data'!D98 -> January | E98: ='Cleaned Data'!E98 -> 144.9 | F98: ='Cleaned Data'!F98 -> 190.1 | G98: ='Cleaned Data'!G98 -> 175.3 | H98: ='Cleaned Data'!H98 -> 154.1 | ... AE98: ='Cleaned Data'!AE98 -> 157.3
A99: ='Cleaned Data'!A99 -> 44228 | B99: ='Cleaned Data'!B99 -> Rural+Urban | C99: ='Cleaned Data'!C99 -> 2021 | D99: ='Cleaned Data'!D99 -> February | E99: ='Cleaned Data'!E99 -> 144.3 | F99: ='Cleaned Data'!F99 -> 186.5 | G99: ='Cleaned Data'!G99 -> 168.7 | H99: ='Cleaned Data'!H99 -> 154.7 | ... AE99: ='Cleaned Data'!AE99 -> 156.6
A100: ='Cleaned Data'!A100 -> 44256 | B100: ='Cleaned Data'!B100 -> Rural+Urban | C100: ='Cleaned Data'!C100 -> 2021 | D100: ='Cleaned Data'!D100 -> March | E100: ='Cleaned Data'!E100 -> 144.1 | F100: ='Cleaned Data'!F100 -> 192.2 | G100: ='Cleaned Data'!G100 -> 163.8 | H100: ='Cleaned Data'!H100 -> 154.9 | ... AE100: ='Cleaned Data'!AE100 -> 156.8
A101: ='Cleaned Data'!A101 -> 44287 | B101: ='Cleaned Data'!B101 -> Rural+Urban | C101: ='Cleaned Data'!C101 -> 2021 | D101: ='Cleaned Data'!D101 -> April | E101: ='Cleaned Data'!E101 -> 144.3 | F101: ='Cleaned Data'!F101 -> 198 | G101: ='Cleaned Data'!G101 -> 164.6 | H101: ='Cleaned Data'!H101 -> 155.4 | ... AE101: ='Cleaned Data'!AE101 -> 157.8
A102: ='Cleaned Data'!A102 -> 44317 | B102: ='Cleaned Data'!B102 -> Rural+Urban | C102: ='Cleaned Data'!C102 -> 2021 | D102: ='Cleaned Data'!D102 -> May | E102: ='Cleaned Data'!E102 -> 146.3 | F102: ='Cleaned Data'!F102 -> 200.5 | G102: ='Cleaned Data'!G102 -> 170.3 | H102: ='Cleaned Data'!H102 -> 156.1 | ... AE102: ='Cleaned Data'!AE102 -> 160.4
...

Sheet MoM % Change
A1: Date | B1: Sector | C1: Year | D1: Month | E1: Cereals and products | F1: Meat and fish | G1: Egg | H1: Milk and products | I1: Oils and fats | J1: Fruits | K1: Vegetables | L1: Pulses and products | M1: Sugar and Confectionery | N1: Spices | O1: Non-alcoholic beverages | P1: Prepared meals, snacks, sweets etc. | Q1: Food and beverages | R1: Pan, tobacco and intoxicants | S1: Clothing | T1: Footwear | U1: Clothing and footwear | V1: Housing | W1: Fuel and light | X1: Household goods and services | Y1: Health | Z1: Transport and communication | AA1: Recreation and amusement | AB1: Education | AC1: Personal care and effects | AD1: Miscellaneous | AE1: General index
A2: ='Imputed Data'!A2 -> 41275 | B2: ='Imputed Data'!B2 -> Rural+Urban | C2: ='Imputed Data'!C2 -> 2013 | D2: ='Imputed Data'!D2 -> January
A3: ='Imputed Data'!A3 -> 41306 | B3: ='Imputed Data'!B3 -> Rural+Urban | C3: ='Imputed Data'!C3 -> 2013 | D3: ='Imputed Data'!D3 -> February | E3: =('Imputed Data'!E3-'Imputed Data'!E2)/'Imputed Data'!E2 -> 0.018450185 | F3: =('Imputed Data'!F3-'Imputed Data'!F2)/'Imputed Data'!F2 -> 0.027027027 | G3: =('Imputed Data'!G3-'Imputed Data'!G2)/'Imputed Data'!G2 -> 0.025454545 | H3: =('Imputed Data'!H3-'Imputed Data'!H2)/'Imputed Data'!H2 -> 0.004789272 | I3: =('Imputed Data'!I3-'Imputed Data'!I2)/'Imputed Data'!I2 -> 0.0038058991 | J3: =('Imputed Data'!J3-'Imputed Data'!J2)/'Imputed Data'!J2 -> 0.003875969 | K3: =('Imputed Data'!K3-'Imputed Data'!K2)/'Imputed Data'!K2 -> 0.0097847358 | L3: =('Imputed Data'!L3-'Imputed Data'!L2)/'Imputed Data'!L2 -> -0.0066037736 | ... AE3: =('Imputed Data'!AE3-'Imputed Data'!AE2)/'Imputed Data'!AE2 -> 0.0066921606
A4: ='Imputed Data'!A4 -> 41334 | B4: ='Imputed Data'!B4 -> Rural+Urban | C4: ='Imputed Data'!C4 -> 2013 | D4: ='Imputed Data'!D4 -> March | E4: =('Imputed Data'!E4-'Imputed Data'!E3)/'Imputed Data'!E3 -> 0.009057971 | F4: =('Imputed Data'!F4-'Imputed Data'!F3)/'Imputed Data'!F3 -> -0.0045372051 | G4: =('Imputed Data'!G4-'Imputed Data'!G3)/'Imputed Data'!G3 -> -0.014184397 | H4: =('Imputed Data'!H4-'Imputed Data'!H3)/'Imputed Data'!H3 -> 0.0019065777 | I4: =('Imputed Data'!I4-'Imputed Data'!I3)/'Imputed Data'!I3 -> -0.0056872038 | J4: =('Imputed Data'!J4-'Imputed Data'!J3)/'Imputed Data'!J3 -> 0.016409266 | K4: =('Imputed Data'!K4-'Imputed Data'!K3)/'Imputed Data'!K3 -> -0.0096899225 | L4: =('Imputed Data'!L4-'Imputed Data'!L3)/'Imputed Data'!L3 -> -0.0028490028 | ... AE4: =('Imputed Data'!AE4-'Imputed Data'!AE3)/'Imputed Data'!AE3 -> 0.0018993352
A5: ='Imputed Data'!A5 -> 41365 | B5: ='Imputed Data'!B5 -> Rural+Urban | C5: ='Imputed Data'!C5 -> 2013 | D5: ='Imputed Data'!D5 -> April | E5: =('Imputed Data'!E5-'Imputed Data'!E4)/'Imputed Data'!E4 -> 0.0017953321 | F5: =('Imputed Data'!F5-'Imputed Data'!F4)/'Imputed Data'!F4 -> 0.010938924 | G5: =('Imputed Data'!G5-'Imputed Data'!G4)/'Imputed Data'!G4 -> -0.041366906 | H5: =('Imputed Data'!H5-'Imputed Data'!H4)/'Imputed Data'!H4 -> 0.0057088487 | I5: =('Imputed Data'!I5-'Imputed Data'!I4)/'Imputed Data'!I4 -> -0.0047664442 | J5: =('Imputed Data'!J5-'Imputed Data'!J4)/'Imputed Data'!J4 -> 0.034188034 | K5: =('Imputed Data'!K5-'Imputed Data'!K4)/'Imputed Data'!K4 -> 0.032289628 | L5: =('Imputed Data'!L5-'Imputed Data'!L4)/'Imputed Data'!L4 -> 0.0028571429 | ... AE5: =('Imputed Data'!AE5-'Imputed Data'!AE4)/'Imputed Data'!AE4 -> 0.0056872038
A6: ='Imputed Data'!A6 -> 41395 | B6: ='Imputed Data'!B6 -> Rural+Urban | C6: ='Imputed Data'!C6 -> 2013 | D6: ='Imputed Data'!D6 -> May | E6: =('Imputed Data'!E6-'Imputed Data'!E5)/'Imputed Data'!E5 -> 0.0062724014 | F6: =('Imputed Data'!F6-'Imputed Data'!F5)/'Imputed Data'!F5 -> 0.003606853 | G6: =('Imputed Data'!G6-'Imputed Data'!G5)/'Imputed Data'!G5 -> -0.01782364 | H6: =('Imputed Data'!H6-'Imputed Data'!H5)/'Imputed Data'!H5 -> 0.010406812 | I6: =('Imputed Data'!I6-'Imputed Data'!I5)/'Imputed Data'!I5 -> -0.004789272 | J6: =('Imputed Data'!J6-'Imputed Data'!J5)/'Imputed Data'!J5 -> 0.0036730946 | K6: =('Imputed Data'!K6-'Imputed Data'!K5)/'Imputed Data'!K5 -> 0.07014218 | L6: =('Imputed Data'!L6-'Imputed Data'!L5)/'Imputed Data'!L5 -> 0.0047483381 | ... AE6: =('Imputed Data'!AE6-'Imputed Data'!AE5)/'Imputed Data'!AE5 -> 0.0075400566
A7: ='Imputed Data'!A7 -> 41426 | B7: ='Imputed Data'!B7 -> Rural+Urban | C7: ='Imputed Data'!C7 -> 2013 | D7: ='Imputed Data'!D7 -> June | E7: =('Imputed Data'!E7-'Imputed Data'!E6)/'Imputed Data'!E6 -> 0.013357079 | F7: =('Imputed Data'!F7-'Imputed Data'!F6)/'Imputed Data'!F6 -> 0.032345013 | G7: =('Imputed Data'!G7-'Imputed Data'!G6)/'Imputed Data'!G6 -> 0.048710602 | H7: =('Imputed Data'!H7-'Imputed Data'!H6)/'Imputed Data'!H6 -> 0.010299625 | I7: =('Imputed Data'!I7-'Imputed Data'!I6)/'Imputed Data'!I6 -> 0.0028873917 | J7: =('Imputed Data'!J7-'Imputed Data'!J6)/'Imputed Data'!J6 -> 0.012808783 | K7: =('Imputed Data'!K7-'Imputed Data'!K6)/'Imputed Data'!K6 -> 0.12223206 | L7: =('Imputed Data'!L7-'Imputed Data'!L6)/'Imputed Data'!L6 -> 0.0047258979 | ... AE7: =('Imputed Data'!AE7-'Imputed Data'!AE6)/'Imputed Data'!AE6 -> 0.022450889
A8: ='Imputed Data'!A8 -> 41456 | B8: ='Imputed Data'!B8 -> Rural+Urban | C8: ='Imputed Data'!C8 -> 2013 | D8: ='Imputed Data'!D8 -> July | E8: =('Imputed Data'!E8-'Imputed Data'!E7)/'Imputed Data'!E7 -> 0.0087873462 | F8: =('Imputed Data'!F8-'Imputed Data'!F7)/'Imputed Data'!F7 -> 0.01305483 | G8: =('Imputed Data'!G8-'Imputed Data'!G7)/'Imputed Data'!G7 -> 0.019125683 | H8: =('Imputed Data'!H8-'Imputed Data'!H7)/'Imputed Data'!H7 -> 0.0092678406 | I8: =('Imputed Data'!I8-'Imputed Data'!I7)/'Imputed Data'!I7 -> 0.0009596929 | J8: =('Imputed Data'!J8-'Imputed Data'!J7)/'Imputed Data'!J7 -> 0.0090334237 | K8: =('Imputed Data'!K8-'Imputed Data'!K7)/'Imputed Data'!K7 -> 0.10497238 | L8: =('Imputed Data'!L8-'Imputed Data'!L7)/'Imputed Data'!L7 -> 0.00094073377 | ... AE8: =('Imputed Data'!AE8-'Imputed Data'!AE7)/'Imputed Data'!AE7 -> 0.015553522
A9: ='Imputed Data'!A9 -> 41487 | B9: ='Imputed Data'!B9 -> Rural+Urban | C9: ='Imputed Data'!C9 -> 2013 | D9: ='Imputed Data'!D9 -> August | E9: =('Imputed Data'!E9-'Imputed Data'!E8)/'Imputed Data'!E8 -> 0.0069686411 | F9: =('Imputed Data'!F9-'Imputed Data'!F8)/'Imputed Data'!F8 -> 0.0068728522 | G9: =('Imputed Data'!G9-'Imputed Data'!G8)/'Imputed Data'!G8 -> -0.0017873101 | H9: =('Imputed Data'!H9-'Imputed Data'!H8)/'Imputed Data'!H8 -> 0.0064279155 | I9: =('Imputed Data'!I9-'Imputed Data'!I8)/'Imputed Data'!I8 -> 0.0019175455 | J9: =('Imputed Data'!J9-'Imputed Data'!J8)/'Imputed Data'!J8 -> -0.017009848 | K9: =('Imputed Data'!K9-'Imputed Data'!K8)/'Imputed Data'!K8 -> 0.084285714 | L9: =('Imputed Data'!L9-'Imputed Data'!L8)/'Imputed Data'!L8 -> 0.00093984962 | ... AE9: =('Imputed Data'!AE9-'Imputed Data'!AE8)/'Imputed Data'!AE8 -> 0.012612613
A10: ='Imputed Data'!A10 -> 41518 | B10: ='Imputed Data'!B10 -> Rural+Urban | C10: ='Imputed Data'!C10 -> 2013 | D10: ='Imputed Data'!D10 -> September | E10: =('Imputed Data'!E10-'Imputed Data'!E9)/'Imputed Data'!E9 -> 0.0069204152 | F10: =('Imputed Data'!F10-'Imputed Data'!F9)/'Imputed Data'!F9 -> -0.002559727 | G10: =('Imputed Data'!G10-'Imputed Data'!G9)/'Imputed Data'!G9 -> 0.0053715309 | H10: =('Imputed Data'!H10-'Imputed Data'!H9)/'Imputed Data'!H9 -> 0.0082116788 | I10: =('Imputed Data'!I10-'Imputed Data'!I9)/'Imputed Data'!I9 -> 0.0076555024 | J10: =('Imputed Data'!J10-'Imputed Data'!J9)/'Imputed Data'!J9 -> -0.02276867 | K10: =('Imputed Data'!K10-'Imputed Data'!K9)/'Imputed Data'!K9 -> 0.059947299 | L10: =('Imputed Data'!L10-'Imputed Data'!L9)/'Imputed Data'!L9 -> 0.0056338028 | ... AE10: =('Imputed Data'!AE10-'Imputed Data'!AE9)/'Imputed Data'!AE9 -> 0.011565836
A11: ='Imputed Data'!A11 -> 41548 | B11: ='Imputed Data'!B11 -> Rural+Urban | C11: ='Imputed Data'!C11 -> 2013 | D11: ='Imputed Data'!D11 -> October | E11: =('Imputed Data'!E11-'Imputed Data'!E10)/'Imputed Data'!E10 -> 0.0060137457 | F11: =('Imputed Data'!F11-'Imputed Data'!F10)/'Imputed Data'!F10 -> -0.005132592 | G11: =('Imputed Data'!G11-'Imputed Data'!G10)/'Imputed Data'!G10 -> 0.0089047195 | H11: =('Imputed Data'!H11-'Imputed Data'!H10)/'Imputed Data'!H10 -> 0.0063348416 | I11: =('Imputed Data'!I11-'Imputed Data'!I10)/'Imputed Data'!I10 -> 0.0037986705 | J11: =('Imputed Data'!J11-'Imputed Data'!J10)/'Imputed Data'!J10 -> 0.024231128 | K11: =('Imputed Data'!K11-'Imputed Data'!K10)/'Imputed Data'!K10 -> 0.064014916 | L11: =('Imputed Data'!L11-'Imputed Data'!L10)/'Imputed Data'!L10 -> 0.0018674136 | ... AE11: =('Imputed Data'!AE11-'Imputed Data'!AE10)/'Imputed Data'!AE10 -> 0.0096745822
